Workbook

Sheet Code
B3: Stock Take List
B4: Cost Center
B5: Date
B7: Item No. | D7: Item | E7: Unit | G7: Count Qty
B8: Unassigned
C9: Bakery
C10: Bread | D10: 100001 | E10: Each
C11: Bread Crumbs | D11: 100005 | E11: Pkt 1 Kg
C12: Bread Darker | D12: 100021 | E12: Kilogram
C13: Bread Sour Dough | D13: 100020 | E13: Each
C14: Brownie can | D14: 100037 | E14: Each
C15: Cookies (not use) | D15: 100022 | E15: Each
C16: Cookies chocolate | D16: 100026 | E16: Each
C17: Cookies not use | D17: 100035 | E17: Order 8 pieces
C18: Frozen Pan Suisse Chocolate | D18: 100032 | E18: Each
C19: Frozen Plain Croissant | D19: 100031 | E19: Each
C20: Milk Powder Nido | D20: 100051 | E20: Pkt 1.75 Kg
C21: Pretzel Bread (PA) | D21: 100017 | E21: Each
... C27: Tortilla Bread | D27: 100008 | E27: Each
D28: Beverage
C29: Cubie Pistachio Sauce | D29: 200158 | E29: Btl 1 L
C30: Dvg Syrup Raspberry | D30: 200101 | E30: Btl 750 Ml
C31: Dvg Syrup Strawberry | D31: 200097 | E31: Btl 750 Ml
C32: Ice cube | D32: 200143 | E32: Kilogram
C33: Juice Apple Juhayna | D33: 200218 | E33: Liter
C34: Juice Pineapple Juhayna | D34: 200119 | E34: Btl 1 L
C35: Keddy strawberry syrup | D35: 200172 | E35: Liter
C36: Pistachio sauce | D36: 200078 | E36: BTL 900 GR
C37: Red food color | D37: 200142 | E37: Btl 1 L
C38: Red Grape Juice Juihaina | D38: 200096 | E38: Kilogram
E39: Can 330 Ml
C40: Soda Cans Cola 24 Can | D40: 200013 | E40: Pkt 1 L
C41: Soda Schweppes | D41: 200006 | E41: Btl 1 L
C42: Syrup coconut Brix | D42: 200095 | E42: Btl 1 L
C43: Syrup Coconut Monin | D43: 200111 | E43: Btl 1 L
C44: Syrup Monin Mango puree Box 4 botl * 1 lit | D44: 200016 | E44: Btl 1 L
C45: Syrup Monin Raspberry puree | D45: 200023 | E45: Btl 1 L
C46: Syrup Monin strawberry puree Box 4 btl 1 lit | D46: 200010 | E46: Btl 600 Ml
C47: Syrup Monin vanilla Box 6 btl 1 lit | D47: 200017 | E47: Gal 19 L
C48: Water 600 Ml Box 20 btl | D48: 200021
...

Sheet ورقة العمل
A1: Item | B1: Item No. | C1: Unit
A2: =IFERROR(VLOOKUP(B2,Code!$C:$E,2,0),"") -> 105049 | B2: Bresaola-SPLIT | C2: =IFERROR(VLOOKUP(B2,Code!$C:$E,3,0),"") -> Kilogram
A3: =IFERROR(VLOOKUP(B3,Code!$C:$E,2,0),"") -> 105051 | B3: Beef Bacon (Core GYM) | C3: =IFERROR(VLOOKUP(B3,Code!$C:$E,3,0),"") -> Kilogram
A4: =IFERROR(VLOOKUP(B4,Code!$C:$E,2,0),"") -> 110296 | B4: Turkey pastrame (PA) | C4: =IFERROR(VLOOKUP(B4,Code!$C:$E,3,0),"") -> Each
A5: =IFERROR(VLOOKUP(B5,Code!$C:$E,2,0),"") -> 104349 | B5: Blueberry Frozen | C5: =IFERROR(VLOOKUP(B5,Code!$C:$E,3,0),"") -> Kilogram
A6: =IFERROR(VLOOKUP(B6,Code!$C:$E,2,0),"") -> 101119 | B6: mozzarella stikcks | C6: =IFERROR(VLOOKUP(B6,Code!$C:$E,3,0),"") -> Kilogram
A7: =IFERROR(VLOOKUP(B7,Code!$C:$E,2,0),"") -> 110050 | B7: Onion Rings Fried . (PA) | C7: =IFERROR(VLOOKUP(B7,Code!$C:$E,3,0),"") -> Portion
A8: =IFERROR(VLOOKUP(B8,Code!$C:$E,2,0),"") -> 100037 | B8: Brownie can | C8: =IFERROR(VLOOKUP(B8,Code!$C:$E,3,0),"") -> Each
A9: =IFERROR(VLOOKUP(B9,Code!$C:$E,2,0),"") -> 108133 | B9: Rasberry Frozen | C9: =IFERROR(VLOOKUP(B9,Code!$C:$E,3,0),"") -> Kilogram
A10: =IFERROR(VLOOKUP(B10,Code!$C:$E,2,0),"") -> 105003 | B10: Chicken Breast | C10: =IFERROR(VLOOKUP(B10,Code!$C:$E,3,0),"") -> Pkt 1 Kg
A11: =IFERROR(VLOOKUP(B11,Code!$C:$E,2,0),"") -> 108163 | B11: Strawberry frozen | C11: =IFERROR(VLOOKUP(B11,Code!$C:$E,3,0),"") -> Pkt 400 Gr
A12: =IFERROR(VLOOKUP(B12,Code!$C:$E,2,0),"") -> 108108 | B12: Fresh Celery | C12: =IFERROR(VLOOKUP(B12,Code!$C:$E,3,0),"") -> Pkt 100 Gr
A13: =IFERROR(VLOOKUP(B13,Code!$C:$E,2,0),"") -> 105026 | B13: Fresh Turkey | C13: =IFERROR(VLOOKUP(B13,Code!$C:$E,3,0),"") -> Kilogram
... A381: =IFERROR(VLOOKUP(B381,Code!$C:$E,2,0),"") -> 104408 | B381: Cherry Frozen | C381: =IFERROR(VLOOKUP(B381,Code!$C:$E,3,0),"") -> Kilogram
A382: =IFERROR(VLOOKUP(B382,Code!$C:$E,2,0),"") | C382: =IFERROR(VLOOKUP(B382,Code!$C:$E,3,0),"")
A383: =IFERROR(VLOOKUP(B383,Code!$C:$E,2,0),"") | C383: =IFERROR(VLOOKUP(B383,Code!$C:$E,3,0),"")
A384: =IFERROR(VLOOKUP(B384,Code!$C:$E,2,0),"") | C384: =IFERROR(VLOOKUP(B384,Code!$C:$E,3,0),"")
A385: =IFERROR(VLOOKUP(B385,Code!$C:$E,2,0),"") | C385: =IFERROR(VLOOKUP(B385,Code!$C:$E,3,0),"")
A386: =IFERROR(VLOOKUP(B386,Code!$C:$E,2,0),"") | C386: =IFERROR(VLOOKUP(B386,Code!$C:$E,3,0),"")
A387: =IFERROR(VLOOKUP(B387,Code!$C:$E,2,0),"") | C387: =IFERROR(VLOOKUP(B387,Code!$C:$E,3,0),"")
A388: =IFERROR(VLOOKUP(B388,Code!$C:$E,2,0),"") | C388: =IFERROR(VLOOKUP(B388,Code!$C:$E,3,0),"")
A389: =IFERROR(VLOOKUP(B389,Code!$C:$E,2,0),"") | C389: =IFERROR(VLOOKUP(B389,Code!$C:$E,3,0),"")
A390: =IFERROR(VLOOKUP(B390,Code!$C:$E,2,0),"") | C390: =IFERROR(VLOOKUP(B390,Code!$C:$E,3,0),"")
A391: =IFERROR(VLOOKUP(B391,Code!$C:$E,2,0),"") | C391: =IFERROR(VLOOKUP(B391,Code!$C:$E,3,0),"")
A392: =IFERROR(VLOOKUP(B392,Code!$C:$E,2,0),"") | C392: =IFERROR(VLOOKUP(B392,Code!$C:$E,3,0),"")
A393: =IFERROR(VLOOKUP(B393,Code!$C:$E,2,0),"") | C393: =IFERROR(VLOOKUP(B393,Code!$C:$E,3,0),"")
... A1362: =IFERROR(VLOOKUP(B1362,Code!$C:$E,2,0),"") | C1362: =IFERROR(VLOOKUP(B1362,Code!$C:$E,3,0),"")
