Workbook

Sheet التقرير
A3: Stock Take List | E3: INV2607-0308
A4: Cost Center | E4: Center Kitchen CC
A5: Date | E5: 46234
A7: Item No. | D7: Item | F7: Unit
A8: Unassigned
B9: Bakery
B10: 1 | D10: Sauce Brgr | F10: Kilogram
B11: 100001 | D11: Bread | F11: Each
B12: 100005 | D12: Bread Crumbs | F12: Pkt 1 Kg
B13: 100021 | D13: Bread Darker | E13: Bread Darker | F13: Kilogram
B14: 100020 | D14: Bread Sour Dough | E14: Bread Sour Dough | F14: Each
B15: 100037 | D15: Brownie can | E15: Brownie can | F15: Each
B16: 100022 | D16: Cookies (not use) | E16: Cookies (not use) | F16: Each
B17: 100026 | D17: Cookies chocolate | E17: Cookies chocolate | F17: Each
B18: 100035 | D18: Cookies not use | E18: Cookies not use | F18: Order 8 pieces
B19: 100032 | D19: Frozen Pan Suisse Chocolate | E19: Frozen Pan Suisse Chocolate | F19: Each
B20: 100031 | D20: Frozen Plain Croissant | E20: Frozen Plain Croissant | F20: Each
B21: 100051 | D21: Milk Powder Nido | E21: Milk Powder Nido | F21: Pkt 1.75 Kg
B22: 100017 | D22: Pretzel Bread (PA) | E22: Pretzel Bread (PA) | F22: Each
B23: 100016 | D23: Pretzel bread water | E23: Pretzel bread water | F23: Gal 5 L
B24: 100010 | D24: Sesame bread | E24: Sesame bread | F24: Each
... B28: 100008 | D28: Tortilla Bread | E28: Tortilla Bread | F28: Each
B29: Beverage
B30: 200158 | D30: Cubie Pistachio Sauce | F30: Btl 1 L
B31: 200101 | D31: Dvg Syrup Raspberry | F31: Btl 750 Ml
B32: 200097 | D32: Dvg Syrup Strawberry | F32: Btl 750 Ml
B33: 200143 | D33: Ice cube | F33: Kilogram
B34: 200218 | D34: Juice Apple Juhayna | F34: Liter
B35: 200119 | D35: Juice Pineapple Juhayna | F35: Btl 1 L
B36: 200172 | D36: Keddy strawberry syrup | F36: Liter
B37: 200078 | D37: Pistachio sauce | F37: BTL 900 GR
B38: 200142 | D38: Red food color | F38: Liter
B39: 200096 | D39: Red Grape Juice Juihaina | F39: Btl 1 L
B40: 200013 | D40: Soda Cans Cola 24 Can | F40: Can 330 Ml
B41: 200006 | D41: Soda Schweppes | F41: Btl 1 L
... B49: 200012 | D49: Water Gallon 19 lit | F49: Gal 19 L
B50: Cleaning Supplies
B51: 600062 | D51: Air Freshener Spray | F51: Each
B52: 600015 | D52: Bacteria Tablets | F52: Box 200 Pcs
B53: 600036 | D53: Broom | F53: Each
...

Sheet Sheet1
B3: Stock Take List | F3: INV2507-0304
B4: Cost Center | F4: Center Kitchen CC
B5: Date | F5: 46203
B7: Item No. | E7: Item | G7: Unit | I7: Count Qty
B8: Unassigned
C9: Bakery
C10: 1 | E10: Sauce Brgr | G10: Kilogram | I10: =SUMIFS(#REF!,#REF!,التقرير!B10) -> #REF!
C11: 100001 | E11: Bread | G11: Each | I11: =SUMIFS(#REF!,#REF!,التقرير!B11) -> #REF!
C12: 100005 | E12: Bread Crumbs | G12: Pkt 1 Kg | I12: =SUMIFS(#REF!,#REF!,التقرير!B12) -> #REF!
C13: 100021 | E13: Bread Darker | F13: Bread Darker | G13: Kilogram | I13: =SUMIFS(#REF!,#REF!,التقرير!B13) -> #REF!
C14: 100020 | E14: Bread Sour Dough | F14: Bread Sour Dough | G14: Each | I14: =SUMIFS(#REF!,#REF!,التقرير!B14) -> #REF!
C15: 100037 | E15: Brownie can | F15: Brownie can | G15: Each | I15: =SUMIFS(#REF!,#REF!,التقرير!B15) -> #REF!
C16: 100022 | E16: Cookies (not use) | F16: Cookies (not use) | G16: Each | I16: =SUMIFS(#REF!,#REF!,التقرير!B16) -> #REF!
C17: 100026 | E17: Cookies chocolate | F17: Cookies chocolate | G17: Each | I17: =SUMIFS(#REF!,#REF!,التقرير!B17) -> #REF!
C18: 100035 | E18: Cookies not use | F18: Cookies not use | G18: Order 8 pieces | I18: =SUMIFS(#REF!,#REF!,التقرير!B18) -> #REF!
C19: 100032 | E19: Frozen Pan Suisse Chocolate | F19: Frozen Pan Suisse Chocolate | G19: Each | I19: =SUMIFS(#REF!,#REF!,التقرير!B19) -> #REF!
C20: 100031 | E20: Frozen Plain Croissant | F20: Frozen Plain Croissant | G20: Each | I20: =SUMIFS(#REF!,#REF!,التقرير!B20) -> #REF!
C21: 100051 | E21: Milk Powder Nido | F21: Milk Powder Nido | G21: Pkt 1.75 Kg | I21: =SUMIFS(#REF!,#REF!,التقرير!B21) -> #REF!
C22: 100017 | E22: Pretzel Bread (PA) | F22: Pretzel Bread (PA) | G22: Each | I22: =SUMIFS(#REF!,#REF!,التقرير!B22) -> #REF!
C23: 100016 | E23: Pretzel bread water | F23: Pretzel bread water | G23: Gal 5 L | I23: =SUMIFS(#REF!,#REF!,التقرير!B23) -> #REF!
C24: 100010 | E24: Sesame bread | F24: Sesame bread | G24: Each | I24: =SUMIFS(#REF!,#REF!,التقرير!B24) -> #REF!
... C28: 100008 | E28: Tortilla Bread | F28: Tortilla Bread | G28: Each | I28: =SUMIFS(#REF!,#REF!,التقرير!B28) -> #REF!
C29: Beverage | I29: =SUMIFS(#REF!,#REF!,التقرير!B29) -> #REF!
C30: 200158 | E30: Cubie Pistachio Sauce | G30: Btl 1 L | I30: =SUMIFS(#REF!,#REF!,التقرير!B30) -> #REF!
C31: 200101 | E31: Dvg Syrup Raspberry | G31: Btl 750 Ml | I31: =SUMIFS(#REF!,#REF!,التقرير!B31) -> #REF!
C32: 200097 | E32: Dvg Syrup Strawberry | G32: Btl 750 Ml | I32: =SUMIFS(#REF!,#REF!,التقرير!B32) -> #REF!
C33: 200143 | E33: Ice cube | G33: Kilogram | I33: =SUMIFS(#REF!,#REF!,التقرير!B33) -> #REF!
C34: 200218 | E34: Juice Apple Juhayna | G34: Liter | I34: =SUMIFS(#REF!,#REF!,التقرير!B34) -> #REF!
C35: 200119 | E35: Juice Pineapple Juhayna | G35: Btl 1 L | I35: =SUMIFS(#REF!,#REF!,التقرير!B35) -> #REF!
C36: 200172 | E36: Keddy strawberry syrup | G36: Liter | I36: =SUMIFS(#REF!,#REF!,التقرير!B36) -> #REF!
C37: 200078 | E37: Pistachio sauce | G37: BTL 900 GR | I37: =SUMIFS(#REF!,#REF!,التقرير!B37) -> #REF!
C38: 200142 | E38: Red food color | G38: Liter | I38: =SUMIFS(#REF!,#REF!,التقرير!B38) -> #REF!
C39: 200096 | E39: Red Grape Juice Juihaina | G39: Btl 1 L | I39: =SUMIFS(#REF!,#REF!,التقرير!B39) -> #REF!
C40: 200174 | E40: Salted hazelnut (PA) | G40: Kilogram | I40: =SUMIFS(#REF!,#REF!,التقرير!B633) -> #REF!
C41: 200013 | E41: Soda Cans Cola 24 Can | G41: Can 330 Ml | I41: =SUMIFS(#REF!,#REF!,التقرير!B40) -> #REF!
C42: 200006 | E42: Soda Schweppes | G42: Btl 1 L | I42: =SUMIFS(#REF!,#REF!,التقرير!B41) -> #REF!
C43: 200095 | E43: Syrup coconut Brix | G43: Pkt 1 L | I43: =SUMIFS(#REF!,#REF!,التقرير!B42) -> #REF!
C44: 200111 | E44: Syrup Coconut Monin | G44: Btl 1 L | I44: =SUMIFS(#REF!,#REF!,التقرير!B43) -> #REF!
C45: 200016 | E45: Syrup Monin Mango puree Box 4 botl * 1 lit | G45: Btl 1 L | I45: =SUMIFS(#REF!,#REF!,التقرير!B44) -> #REF!
C46: 200023 | E46: Syrup Monin Raspberry puree | G46: Btl 1 L | I46: =SUMIFS(#REF!,#REF!,التقرير!B45) -> #REF!
...
